Workbook
Name 목록_단위: DATA!$A$1:$A$2

Sheet 연구비계상(과제책임자용)
AA1: <업데이트> 2021.02.23. 위탁연구비 고려 간접비 계산 2021.03.16. 간접비율,간접성경비비율,위탁연구비 등 if문 삭제 (직관성 확보 목적) 2021.06.22. 간접성경비 계산에 부가세 포함되지 않도록 변경 2021.12.15. 국제협력비 수정
I2: 비목 | J2: 세목 | K2: 세세목 | L2: ="예산("&D6&")" -> 예산(천원) | N2: 비목 | O2: 세목 | P2: 세세목 | R2: ="예산("&D6&")" -> 예산(천원)
C3: ※ 작성 전 확인 ※ (노란셀만 수정) | I3: 직접비 | J3: 인건비 | K3: 내부인건비 | L3: =SUMIF(인건비계상기준!$A:$A,$K$3,인건비계상기준!I:I) -> 30000000 | N3: 직접비 | O3: 연구재료비 | P3: 연구재료 구입비
K4: 외부인건비 | L4: =SUMIF(인건비계상기준!$A:$A,$K$4,인건비계상기준!I:I) -> 0 | P4: 연구개발과제 관리비(전산처리비)
K5: 학생인건비 | L5: =SUMIF(인건비계상기준!$A:$A,$K$5,인건비계상기준!I:I) -> 0 | P5: 연구재료 제작비
C6: 입력단위 | D6: 천원 | K6: 미지급인건비 | L6: =SUMIF(인건비계상기준!$A:$A,$K$6,인건비계상기준!I:I) -> 0 | O6: 연구수당 | P6: 연구활동진흥비
J7: 연구시설/장비비 | K7: 연구장비구입비 | O7: 연구개발부담비 | P7: 연구개발부담비
C8: 1. 우선 입력 후 확인 사항 | K8: 연구시설비 | O8: 위탁연구개발비 | P8: 위탁연구개발비
C9: 전체 차수 연구비 총액 (미지급인건비, 부가세 제외) | D9: 0 | F9: =IF(D6="원",D9,IF(D6="천원",D9*1000,IF(D6="백만원",D9*1000000))) -> 0 | K9: 연구장비유지비 | O9: 직접비 소계 (미지급인건비 제외) | R9: =SUM(L3:L5,L7:L40,R3:R8) -> 30000000
C10: 당 차수 연구비 총액 (미지급인건비, 부가세 제외) | D10: 0 | K10: 연구시설장비임대차비 | N10: 간접비 | O10: 성과활용지원비 | P10: 지식재산권 출원등록비(수탁사업)
C11: 간접비 적용비율 | D11: 0.1906 | J11: 연구활동비 | K11: 국외여비 | P11: 과학문화활동비(수탁사업)
C12: 연구실안전관리비 비율 | D12: 0.01 | K12: 국내여비 | P12: 기술창업 출연 출자금(수탁사업)
C13: 권장 직접비 총액 | D13: =D10-D14 -> 0 | K13: 유인물비 | O13: 연구지원비 | P13: 기반시설ㆍ장비구축ㆍ운영비(수탁사업)
C14: 권장 간접비 총액 | D14: =ROUNDDOWN((D10-R8-L39)/(1+1/D11),0) -> 0 | K14: 제세공과금 | P14: 기관공통지원경비(수탁사업) | R14: =D14-R15 -> -300000
C15: 최소 내부인건비 권장액 | D15: =ROUNDUP((D10-L39-R8)*0.4-R19,0) -> 0 | K15: 수수료 | P15: 연구실안전관리비(수탁사업) | R15: =SUM(L3:L6)*D12 -> 300000
C16: 연구수당 한도액 | D16: =ROUNDDOWN(SUM(L3:L6)*0.2,0) -> 6000000 | K16: 국내외훈련비 | P16: 연구보안관리비(수탁사업)
K17: 문헌구입비 | P17: 연구윤리활동비(수탁사업)
C18: 2. 다음 입력 사항 | K18: 세미나참가비 | P18: 연구활동지원금(수탁사업)
C19: K열, Q열의 노란색 셀 입력 | K19: 세미나(행사)개최비 | O19: 간접비 소계 | R19: =SUM(R10:R18) -> 0
K20: 기술도입비 | N20: 연구비 총액 (미지급인건비, 부가세 제외) | R20: =R9+R19 -> 30000000
K21: 논문게재료 | N21: 부가가치세 | R21: 0
K22: 원고료 | N22: 연구비 총액 (미지급인건비 제외) | R22: =R20+R21 -> 30000000
K23: 강사료
C24: 협약 연구비와 차액 파악용 (Optional) | K24: 국내외훈련비 | N24: 개인 메모/계산용 | Q24: 연구업무심의회 생략 조건
K25: 연구개발서비스활용비 | Q25: ="ㅇ 총 연구비("&D6&") (10억원 미만)" -> ㅇ 총 연구비(천원) (10억원 미만) | R25: =IF(Q26<1000000000,"[연심생략]","[연심대상]") -> [연심생략]
K26: 전문가활용비 | Q26: =D9*1000 -> 0
C27: 세목 | D27: 협약 연구비 | E27: 차액 | K27: 시험분석료 | Q27: ㅇ 간접성경비 비율 (40% 이상) | R27: =IF((R20-R21-R8)<>0,IF(Q28>=40%,"[연심생략]","[연심대상]"),"-") -> [연심생략]
C28: 인건비 (미지급 제외) | E28: =SUM(L3:L5)-D28 -> 30000000 | K28: 세부과제관리비 | Q28: =(L3+R19)/(R20-R8) -> 1
C29: 연구시설/장비비 | E29: =SUM(L7:L10)-D29 -> 0 | K29: 특허관리비 | Q29: ="ㅇ *간접비 비율 ("&ROUND(D11*100,2)&"%)" -> ㅇ *간접비 비율 (19.06%) | R29: =IF((R9-R8)<>0,IF(AND(Q30>=D11-0.005%,Q30<=D11),"[연심생략]",IF(Q30<D11-0.005%,"[연심대상]","[하향필요]")),"-") -> [연심대상]
C30: 연구활동비 | E30: =SUM(L11:L40)-D30 -> 0 | K30: 해외연구소 설치 및 운영 | Q30: =R19/(R9-R8-L39-R7) -> 0
C31: 연구재료비 | E31: =SUM(R3:R5)-D31 -> 0 | K31: 지식재산창출활동비
C32: 연구수당 | E32: =R6-D32 -> 0 | K32: 회의비 | Q32: *국가연구개발혁신법
C33: 위탁연구개발비 | E33: =R8-D33 -> 0 | K33: 사무용품비 | Q33: ㅇ *연구수당 (20% 이하) | R33: =IF(SUM(L3:L6)<>0,IF(Q34<=20%,"[적합]","[부적합]"),"-") -> [적합]
C34: 직접비 소계 | D34: =SUM(D28:D33) -> 0 | E34: =SUM(E28:E33)-D34 -> 30000000 | K34: 연구실환경유지비 | Q34: =R6/SUM(L3:L6) -> 0
C35: 연구실안전관리비 | E35: =R15-D35 -> 300000 | K35: 사무장비구입비 | Q35: ㅇ *연구실안전관리비 (1~2%) | R35: =IF(SUM(L3:L6)<>0,IF(AND(Q36>=1%),"[적합]","[부적합]"),"-") -> [적합]
C36: 기타 간접비 | D36: =D37-D35 -> 0 | E36: =R19-R15-D36 -> -300000 | K36: 해외 연구자 유치지원비 | Q36: =R15/SUM(L3:L6) -> 0.01
C37: 간접비 소계 | E37: =R19-D37 -> 0 | K37: 일용직 활용비 | Q37: ㅇ *위탁연구개발비 (40% 이하) | R37: =IF(Q38<=0.4,"[적합]","[부적합]") -> [적합]
C38: 부가가치세 | E38: =R21-D38 -> 0 | K38: 소프트웨어활용비 | Q38: =R8/SUM(L3:L5,L7:L30,L31:L40,R3:R6) -> 0
C39: 연구비 총액 | D39: =D34+D37+D38 -> 0 | E39: =R20-D39 -> 30000000 | J39: 국제공동연구개발비 | K39: 국제공동연구개발비 | Q39: ㅇ *전문기술 활용비 (40% 이하) | R39: =IF(Q40<=40%,"[적합]","[부적합]") -> [적합]
J40: 보안수당 | K40: 보안수당 | L40: 0 | Q40: =(L20+L22+L23+L26)/R9 -> 0
...

Sheet 인건비계상기준
A1: 구분 | B1: 사번 | C1: 성명 | D1: 추정인건비 (단위: 원) | E1: 참여시작일 | F1: 참여종료일 | G1: 참여개월수 | H1: 인건비계상률 | I1: 인건비(단위 : 원)
A2: 내부인건비 | D2: 5000000 | E2: 46023 | F2: 46387 | G2: =(YEAR(F2)-YEAR(E2))*12+MONTH(F2)-MONTH(E2)+1 -> 12 | H2: 0.5 | I2: =D2*G2*H2 -> 30000000 | K2: 1. 추정인건비는 사업관리실 담당자 박진아선생님께 참여자들의 추정인건비 정보 요청 - 추정인건비는 해당참여자에게 지급하는 급여(4대보험금, 기관/개인부담금 및 퇴직금 포함) 2. 기간별 참여율이 변경되는 경우는 구분하여 작성
A3: 내부인건비 | E3: 46023 | F3: 46387 | G3: =(YEAR(F3)-YEAR(E3))*12+MONTH(F3)-MONTH(E3)+1 -> 12 | I3: =D3*G3*H3 -> 0
A4: 외부인건비 | E4: 46023 | F4: 46387 | G4: =(YEAR(F4)-YEAR(E4))*12+MONTH(F4)-MONTH(E4)+1 -> 12 | I4: =D4*G4*H4 -> 0
A5: 학생인건비 | E5: 46023 | F5: 46387 | G5: =(YEAR(F5)-YEAR(E5))*12+MONTH(F5)-MONTH(E5)+1 -> 12 | I5: =D5*G5*H5 -> 0
A6: 미지급인건비 | E6: 46023 | F6: 46387 | G6: =(YEAR(F6)-YEAR(E6))*12+MONTH(F6)-MONTH(E6)+1 -> 12 | I6: =D6*G6*H6 -> 0
E7: 46023 | F7: 46387 | G7: =(YEAR(F7)-YEAR(E7))*12+MONTH(F7)-MONTH(E7)+1 -> 12 | I7: =D7*G7*H7 -> 0
E8: 46023 | F8: 46387 | G8: =(YEAR(F8)-YEAR(E8))*12+MONTH(F8)-MONTH(E8)+1 -> 12 | I8: =D8*G8*H8 -> 0
E9: 46023 | F9: 46387 | G9: =(YEAR(F9)-YEAR(E9))*12+MONTH(F9)-MONTH(E9)+1 -> 12 | I9: =D9*G9*H9 -> 0
E10: 46023 | F10: 46387 | G10: =(YEAR(F10)-YEAR(E10))*12+MONTH(F10)-MONTH(E10)+1 -> 12 | I10: =D10*G10*H10 -> 0
E11: 46023 | F11: 46387 | G11: =(YEAR(F11)-YEAR(E11))*12+MONTH(F11)-MONTH(E11)+1 -> 12 | I11: =D11*G11*H11 -> 0
E12: 46023 | F12: 46387 | G12: =(YEAR(F12)-YEAR(E12))*12+MONTH(F12)-MONTH(E12)+1 -> 12 | I12: =D12*G12*H12 -> 0
E13: 46023 | F13: 46387 | G13: =(YEAR(F13)-YEAR(E13))*12+MONTH(F13)-MONTH(E13)+1 -> 12 | I13: =D13*G13*H13 -> 0
E14: 46023 | F14: 46387 | G14: =(YEAR(F14)-YEAR(E14))*12+MONTH(F14)-MONTH(E14)+1 -> 12 | I14: =D14*G14*H14 -> 0
E15: 46023 | F15: 46387 | G15: =(YEAR(F15)-YEAR(E15))*12+MONTH(F15)-MONTH(E15)+1 -> 12 | I15: =D15*G15*H15 -> 0
E16: 46023 | F16: 46387 | G16: =(YEAR(F16)-YEAR(E16))*12+MONTH(F16)-MONTH(E16)+1 -> 12 | I16: =D16*G16*H16 -> 0
E17: 46023 | F17: 46387 | G17: =(YEAR(F17)-YEAR(E17))*12+MONTH(F17)-MONTH(E17)+1 -> 12 | I17: =D17*G17*H17 -> 0
E18: 46023 | F18: 46387 | G18: =(YEAR(F18)-YEAR(E18))*12+MONTH(F18)-MONTH(E18)+1 -> 12 | I18: =D18*G18*H18 -> 0
... E39: 46023 | F39: 46387 | G39: =(YEAR(F39)-YEAR(E39))*12+MONTH(F39)-MONTH(E39)+1 -> 12 | I39: =D39*G39*H39 -> 0
I40: =D40*G40*H40 -> 0

Sheet 연구비총괄표(연구업무심의회용)
B2: 연구비총괄표
B4: 사업명
B5: 과제명
B6: 과제책임자
B7: 당해/전체 연구기간 | D7: 12 개월
B8: 당해/전체 연구비 | D8: 100,000,000원
B10: 비목 | C10: 세목 | D10: 세세목 | E10: ="예산("&'연구비계상(과제책임자용)'!D6&")" -> 예산(천원) | G10: 연구업무심의회 적정성 검토
B11: 직접비 | C11: 인건비 | D11: 내부인건비 | E11: ='연구비계상(과제책임자용)'!L3 -> 30000000 | G11: 내 용 | H11: 적정성 | I11: 비고
D12: 기타인건비 | E12: =SUM('연구비계상(과제책임자용)'!L4:L5) -> 0 | G12: 총 연구비 10억원 미만 | H12: =IF('연구비계상(과제책임자용)'!D9<1000000,"적정","부적정") -> 적정 | I12: 총 연구비(천원) | J12: ='연구비계상(과제책임자용)'!D9 -> 0
D13: 미지급인건비 | E13: ='연구비계상(과제책임자용)'!L6 -> 0 | G13: 간접비 비율 (직접비의 19.06%) | H13: =IF(AND('연구비계상(과제책임자용)'!D11-0.005<='연구비계상(과제책임자용)'!Q30,'연구비계상(과제책임자용)'!Q30<='연구비계상(과제책임자용)'!D11),"적정","부적정") -> 부적정 | I13: 간접비 비율 | J13: ='연구비계상(과제책임자용)'!Q30 -> 0
C14: 연구시설/장비비 | E14: =SUM('연구비계상(과제책임자용)'!L7:L10) -> 0 | G14: 간접성경비 비율 (총연구비의 40% 이상) | H14: =IF('연구비계상(과제책임자용)'!Q28>=40%,"적정","부적정") -> 적정 | I14: 간접성경비 비율 | J14: ='연구비계상(과제책임자용)'!Q28 -> 1
C15: 연구활동비 | E15: =SUM('연구비계상(과제책임자용)'!L11:L40) -> 0
C16: 연구재료비 | E16: =SUM('연구비계상(과제책임자용)'!R3:R5) -> 0 | G16: 과기부 공동관리규정 적정성 검토
C17: 연구수당 | E17: ='연구비계상(과제책임자용)'!R6 -> 0 | G17: 내 용 | H17: 적정성 | I17: 비고
C18: 위탁연구개발비 | E18: ='연구비계상(과제책임자용)'!R8 -> 0 | G18: 연구수당 (인건비의 20% 이하) | H18: =IF(J18<=20,"적정","부적정") -> 적정 | I18: 연구수당 비율 | J18: ='연구비계상(과제책임자용)'!Q34 -> 0
C19: 직접비 소계 | E19: =SUM(E11:E18) -> 30000000 | G19: 위탁연구개발비 (직접비의 40% 이하) | H19: =IF(J19<=40%,"적정","부적정") -> 적정 | I19: 위탁연구비 비율 | J19: ='연구비계상(과제책임자용)'!Q38 -> 0
B20: 간접비 | C20: 기관공통지원경비 | E20: ='연구비계상(과제책임자용)'!R14 -> -300000 | G20: 연구실안전관리비 (인건비의 1~2%) | H20: =IF(AND(J20<=2%,J20>=1%),"적정","부적정") -> 적정 | I20: 안전관리비 비율 | J20: ='연구비계상(과제책임자용)'!Q36 -> 0.01
C21: 연구실안전관리비 | E21: ='연구비계상(과제책임자용)'!R15 -> 300000
C22: 기타 간접비 | E22: =SUM('연구비계상(과제책임자용)'!R10:R13,'연구비계상(과제책임자용)'!R16:R18) -> 0
C23: 간접비 소계 | E23: =SUM(E20:E22) -> 0
B24: 부가가치세 | E24: ='연구비계상(과제책임자용)'!R21 -> 0
B25: 총 연구비 | E25: =E19+E23+E24 -> 30000000

Sheet 회계계정(성과관리팀용)
B2: 기결정보(회계팀)
B3: 기결번호 | C3: 기결일자 | D3: 적요 | E3: 금액(원)
B6: 2번 코드(국가연구개발사업)
B7: 코드번호 | C7: 회계계정 | D7: 금액(원) | E7: 비고
B8: 2106 | C8: 선수금(수탁-내부인건비) | D8: ='연구비계상(과제책임자용)'!L3 -> 30000000 | E8: 내부인건비
B9: 2104 | C9: 선수금(특정수탁-직접비) | D9: ='연구비계상(과제책임자용)'!R9-'연구비계상(과제책임자용)'!L3-'연구비계상(과제책임자용)'!R8 -> 0 | E9: 내부인건비 제외 직접비
B10: 2106 | C10: 선수금(수탁-공통지원경비) | D10: ='연구비계상(과제책임자용)'!R14 -> -300000 | E10: 간접비(기관공통지원경비)
B11: 2122 | C11: 선수금(연구실안전관리비) | D11: ='연구비계상(과제책임자용)'!R15 -> 300000 | E11: 간접비(연구실안전관리비)
B12: 2123 | C12: 선수금(특허출원비) | D12: ='연구비계상(과제책임자용)'!R10 -> 0 | E12: 간접비 (지식재산권 출원등록비)
B13: 2121 | C13: 선수금(과학문화활동비) | D13: ='연구비계상(과제책임자용)'!R11 -> 0 | E13: 간접비
B14: 2104 | C14: 선수금(특) | D14: ='연구비계상(과제책임자용)'!R8 -> 0 | E14: 위탁연구개발비
B15: 2126 | C15: 예수금(부가가치세) | D15: ='연구비계상(과제책임자용)'!R21 -> 0
B16: 2129 | C16: 선수금(특정수탁-이자재투자) | D16: 0
B17: 총액 (부가세 포함) | D17: =SUM(D8:D16)-D14 -> 30000000
B19: 3~9번 코드(공공, 민간, 국제, 연구용역)
B20: 코드번호 | C20: 회계계정 | D20: 금액(원) | E20: 비고
B21: 2106 | C21: 선수금(수탁-내부인건비) | D21: ='연구비계상(과제책임자용)'!L3 -> 30000000 | E21: 내부인건비
B22: 2105 | C22: 선수금(일반수탁-직접비) | D22: ='연구비계상(과제책임자용)'!R9-'연구비계상(과제책임자용)'!L3-'연구비계상(과제책임자용)'!R8 -> 0 | E22: 내부인건비 제외 직접비
B23: 2106 | C23: 선수금(수탁-공통지원경비) | D23: ='연구비계상(과제책임자용)'!R14 -> -300000 | E23: 간접비(기관공통지원경비)
B24: 2122 | C24: 선수금(연구실안전관리비) | D24: ='연구비계상(과제책임자용)'!R15 -> 300000 | E24: 간접비(연구실안전관리비)
B25: 2123 | C25: 선수금(특허출원비) | D25: ='연구비계상(과제책임자용)'!R10 -> 0 | E25: 간접비 (지식재산권 출원등록비)
B26: 2121 | C26: 선수금(과학문화활동비) | D26: ='연구비계상(과제책임자용)'!R11 -> 0 | E26: 간접비
B27: 2104 | C27: 선수금(수) | D27: ='연구비계상(과제책임자용)'!R8 -> 0 | E27: 위탁연구개발비
B28: 2126 | C28: 예수금(부가가치세) | D28: ='연구비계상(과제책임자용)'!R21 -> 0
B29: 2130 | C29: 선수금(일반수탁-이자재투자) | D29: 0
B30: 총액 (부가세 포함) | D30: =SUM(D21:D29)-D27 -> 30000000

Sheet DATA
A1: 원
A2: 천원
